Workbook

Sheet Sheet1
A1: ENGINEER II SHIFTING SCHEDULE
A2: For the month of January 2024
A3: Name of | B3: MON | C3: TUE | D3: WED | E3: THU | F3: FRI | G3: SAT | H3: SUN | I3: MON | J3: TUE | K3: WED | L3: THU | M3: FRI | N3: SAT | O3: SUN | P3: MON | Q3: TUE | R3: WED | S3: THU | T3: FRI | U3: SAT | V3: SUN | W3: MON | X3: TUE | Y3: WED | Z3: THU | AA3: FRI | AB3: SAT | AC3: SUN | AD3: MON | AE3: TUE | AF3: WED
A4: Personnel | B4: 1 | C4: 2 | D4: 3 | E4: 4 | F4: 5 | G4: 6 | H4: 7 | I4: 8 | J4: 9 | K4: 10 | L4: 11 | M4: 12 | N4: 13 | O4: 14 | P4: 15 | Q4: 16 | R4: 17 | S4: 18 | T4: 19 | U4: 20 | V4: 21 | W4: 22 | X4: 23 | Y4: 24 | Z4: 25 | AA4: 26 | AB4: 27 | AC4: 28 | AD4: 29 | AE4: 30 | AF4: 31 | AG4: 24
A5: MACUNTE | B5: DO | C5: R | D5: R | E5: R | F5: R | G5: 2 | H5: DO | I5: R | J5: R | K5: R | L5: R | M5: R | N5: DO | O5: 2 | P5: R | Q5: R | R5: R | S5: R | T5: R | U5: DO | V5: 2 | W5: R | X5: R | Y5: R | Z5: R | AA5: R | AB5: DO | AC5: 2 | AD5: R | AE5: R | AF5: R | AG5: =AR5 -> 26 | AH5: =COUNTIF($B5:$AF5,4) -> 0 | AJ5: =COUNTIF($B5:$AF5,3) -> 0 | AK5: =COUNTIF($B5:$AF5,1) -> 0 | AL5: =COUNTIF($B5:$AF5,2) -> 4 | AM5: =COUNTIF($B5:$AF5,"DO") -> 5 | AN5: =COUNTIF($B5:$AF5,"R") -> 22 | AO5: =COUNTIF($B5:$AF5,4) -> 0 | AP5: =COUNTIF($B5:$AF5,5) -> 0 | AQ5: =SUM(AJ5:AN5) -> 31 | AR5: =AP5+AO5+AN5+AL5+AK5+AJ5+((AH5+AI5)/2) -> 26
A7: ALFECHE | B7: 2 | C7: 5 | D7: 1 | E7: 2 | F7: 3 | G7: 1 | H7: 5 | I7: 1 | J7: 3 | K7: 1 | L7: 3 | M7: 4 | N7: DO | O7: 3 | P7: 1 | Q7: 2 | R7: 3 | S7: 1 | T7: 2 | U7: 3 | V7: 1 | W7: DO | X7: 3 | Y7: 1 | Z7: 3 | AA7: 4 | AB7: DO | AC7: DO | AD7: 3 | AE7: 4 | AF7: 5 | AG7: =AR7 -> 30 | AH7: =COUNTIF($B7:$AF7,4) -> 3 | AI7: =COUNTIF($B7:$AF7,5) -> 3 | AJ7: =COUNTIF($B7:$AF7,3) -> 9 | AK7: =COUNTIF($B7:$AF7,1) -> 8 | AL7: =COUNTIF($B7:$AF7,2) -> 4 | AM7: =COUNTIF($B7:$AF7,"DO") -> 4 | AN7: =COUNTIF($B7:$AF7,"R") -> 0 | AO7: =COUNTIF($B7:$AF7,4) -> 3 | AP7: =COUNTIF($B7:$AF7,5) -> 3 | AQ7: =SUM(AJ7:AN7) -> 25 | AR7: =AP7+AO7+AN7+AL7+AK7+AJ7+((AH7+AI7)/2) -> 30
A9: MICABALO | B9: 3 | C9: 4 | D9: 2 | E9: 3 | F9: 1 | G9: 3 | H9: 1 | I9: 3 | J9: 4 | K9: 2 | L9: DO | M9: 3 | N9: 1 | O9: 3 | P9: 4 | Q9: 3 | R9: 1 | S9: 3 | T9: 1 | U9: 5 | V9: 1 | W9: 3 | X9: 1 | Y9: 3 | Z9: 1 | AA9: DO | AB9: 3 | AC9: 1 | AD9: 2 | AE9: DO | AF9: DO | AG9: =AR9 -> 29 | AH9: =COUNTIF($B9:$AF9,4) -> 3 | AI9: =COUNTIF($B9:$AF9,5) -> 1 | AJ9: =COUNTIF($B9:$AF9,3) -> 11 | AK9: =COUNTIF($B9:$AF9,1) -> 9 | AL9: =COUNTIF($B9:$AF9,2) -> 3 | AM9: =COUNTIF($B9:$AF9,"DO") -> 4 | AN9: =COUNTIF($B9:$AF9,"R") -> 0 | AO9: =COUNTIF($B9:$AF9,4) -> 3 | AP9: =COUNTIF($B9:$AF9,5) -> 1 | AQ9: =SUM(AJ9:AN9) -> 27 | AR9: =AP9+AO9+AN9+AL9+AK9+AJ9+((AH9+AI9)/2) -> 29
A11: PACTURANAN | B11: 3 | C11: 1 | D11: 3 | E11: 1 | F11: 5 | G11: 1 | H11: 3 | I11: 4 | J11: 5 | K11: 1 | L11: 2 | M11: DO | N11: 2 | O11: DO | P11: 5 | Q11: 1 | R11: 2 | S11: 3 | T11: 1 | U11: DO | V11: DO | W11: 5 | X11: 1 | Y11: 3 | Z11: 1 | AA11: 3 | AB11: 1 | AC11: DO | AD11: 3 | AE11: 1 | AF11: 3 | AG11: =AR11 -> 28.5 | AH11: =COUNTIF($B11:$AF11,4) -> 1 | AI11: =COUNTIF($B11:$AF11,5) -> 4 | AJ11: =COUNTIF($B11:$AF11,3) -> 8 | AK11: =COUNTIF($B11:$AF11,1) -> 10 | AL11: =COUNTIF($B11:$AF11,2) -> 3 | AM11: =COUNTIF($B11:$AF11,"DO") -> 5 | AN11: =COUNTIF($B11:$AF11,"R") -> 0 | AO11: =COUNTIF($B11:$AF11,4) -> 1 | AP11: =COUNTIF($B11:$AF11,5) -> 4 | AQ11: =SUM(AJ11:AN11) -> 26 | AR11: =AP11+AO11+AN11+AL11+AK11+AJ11+((AH11+AI11)/2) -> 28.5
A13: RUDINAS | B13: DO | C13: 3 | D13: 1 | E13: 3 | F13: 4 | G13: 3 | H13: 4 | I13: DO | J13: DO | K13: DO | L13: DO | M13: DO | N13: 3 | O13: 1 | P13: DO | Q13: 3 | R13: 1 | S13: 2 | T13: 3 | U13: 1 | V13: 3 | W13: 1 | X13: 2 | Y13: 2 | Z13: 3 | AA13: 1 | AB13: DO | AC13: 3 | AD13: 1 | AE13: 3 | AF13: 4 | AG13: =AR13 -> 24.5 | AH13: =COUNTIF($B13:$AF13,4) -> 3 | AI13: =COUNTIF($B13:$AF13,5) -> 0 | AJ13: =COUNTIF($B13:$AF13,3) -> 10 | AK13: =COUNTIF($B13:$AF13,1) -> 7 | AL13: =COUNTIF($B13:$AF13,2) -> 3 | AM13: =COUNTIF($B13:$AF13,"DO") -> 8 | AN13: =COUNTIF($B13:$AF13,"R") -> 0 | AO13: =COUNTIF($B13:$AF13,4) -> 3 | AP13: =COUNTIF($B13:$AF13,5) -> 0 | AQ13: =SUM(AJ13:AN13) -> 28 | AR13: =AP13+AO13+AN13+AL13+AK13+AJ13+((AH13+AI13)/2) -> 24.5
A15: LUSPO | B15: 1 | C15: DO | D15: 3 | E15: 1 | F15: DO | G15: DO | H15: DO | I15: 5 | J15: 1 | K15: 3 | L15: 1 | M15: 5 | N15: 1 | O15: DO | P15: DO | Q15: DO | R15: DO | S15: R | T15: 3 | U15: 4 | V15: 3 | W15: 4 | X15: 3 | Y15: 1 | Z15: 2 | AA15: 2 | AB15: 2 | AC15: 3 | AD15: 1 | AE15: 5 | AF15: 1 | AG15: =AR15 -> 25.5 | AH15: =COUNTIF($B15:$AF15,4) -> 2 | AI15: =COUNTIF($B15:$AF15,5) -> 3 | AJ15: =COUNTIF($B15:$AF15,3) -> 6 | AK15: =COUNTIF($B15:$AF15,1) -> 8 | AL15: =COUNTIF($B15:$AF15,2) -> 3 | AM15: =COUNTIF($B15:$AF15,"DO") -> 8 | AN15: =COUNTIF($B15:$AF15,"R") -> 1 | AO15: =COUNTIF($B15:$AF15,4) -> 2 | AP15: =COUNTIF($B15:$AF15,5) -> 3 | AQ15: =SUM(AJ15:AN15) -> 26 | AR15: =AP15+AO15+AN15+AL15+AK15+AJ15+((AH15+AI15)/2) -> 25.5
A18: Legend: | D18: 1 | E18: - | F18: 0000H | H18: - | I18: 0800H | M18: R | N18: - | O18: 0800H | Q18: - | R18: 1700H
D19: 2 | E19: - | F19: 0800H | H19: - | I19: 1600H | M19: DO | N19: - | O19: Day off
D20: 3 | E20: - | F20: 1600H | H20: - | I20: 2400H
D21: 4 | E21: - | F21: 0000H | H21: - | I21: 1200H
D22: 5 | E22: - | F22: 1200H | H22: - | I22: 0000H
A24: Prepared By: | L24: Reviewed By: | Y24: Noted By:
B26: J.O.H. LUSPO | N26: E.L. ADIONG | AA26: D.R.B. CAIRO
B27: Engineer II | N27: Prin. Engr. A, GPD | AA27: Acting-Division Manager, GPD
A30: ENGINEER II SHIFTING SCHEDULE
A31: For the month of February 2024
A32: Name of | B32: THU | C32: FRI | D32: SAT | E32: SUN | F32: MON | G32: TUE | H32: WED | I32: THU | J32: FRI | K32: SAT | L32: SUN | M32: MON | N32: TUE | O32: WED | P32: THU | Q32: FRI | R32: SAT | S32: SUN | T32: MON | U32: TUE | V32: WED | W32: THU | X32: FRI | Y32: SAT | Z32: SUN | AA32: MON | AB32: TUE | AC32: WED | AD32: THU
A33: Personnel | B33: 1 | C33: 2 | D33: 3 | E33: 4 | F33: 5 | G33: 6 | H33: 7 | I33: 8 | J33: 9 | K33: 10 | L33: 11 | M33: 12 | N33: 13 | O33: 14 | P33: 15 | Q33: 16 | R33: 17 | S33: 18 | T33: 19 | U33: 20 | V33: 21 | W33: 22 | X33: 23 | Y33: 24 | Z33: 25 | AA33: 26 | AB33: 27 | AC33: 28 | AD33: 29 | AG33: 24
A34: MACUNTE | B34: R | C34: R | D34: DO | E34: 2 | F34: R | G34: R | H34: R | I34: R | J34: R | K34: 2 | L34: DO | M34: R | N34: R | O34: R | P34: R | Q34: R | R34: DO | S34: 2 | T34: R | U34: R | V34: R | W34: R | X34: R | Y34: DO | Z34: 2 | AA34: R | AB34: R | AC34: R | AD34: R | AG34: =AR34 -> 25 | AH34: =COUNTIF($B34:$AF34,4) -> 0 | AJ34: =COUNTIF($B34:$AF34,3) -> 0 | AK34: =COUNTIF($B34:$AF34,1) -> 0 | AL34: =COUNTIF($B34:$AF34,2) -> 4 | AM34: =COUNTIF($B34:$AF34,"DO") -> 4 | AN34: =COUNTIF($B34:$AF34,"R") -> 21 | AO34: =COUNTIF($B34:$AF34,4) -> 0 | AP34: =COUNTIF($B34:$AF34,5) -> 0 | AQ34: =SUM(AJ34:AN34) -> 29 | AR34: =AP34+AO34+AN34+AL34+AK34+AJ34+((AH34+AI34)/2) -> 25
A36: ALFECHE | B36: 1 | C36: 2 | D36: DO | E36: 3 | F36: 4 | G36: 3 | H36: 1 | I36: 3 | J36: 4 | K36: 3 | L36: 1 | M36: 3 | N36: 1 | O36: DO | P36: 3 | Q36: 1 | R36: DO | S36: 3 | T36: 4 | U36: 5 | V36: 1 | W36: 3 | X36: 1 | Y36: 3 | Z36: 1 | AA36: 3 | AB36: 1 | AC36: 5 | AD36: 1 | AG36: =AR36 -> 28.5 | AH36: =COUNTIF($B36:$AF36,4) -> 3 | AI36: =COUNTIF($B36:$AF36,5) -> 2 | AJ36: =COUNTIF($B36:$AF36,3) -> 10 | AK36: =COUNTIF($B36:$AF36,1) -> 10 | AL36: =COUNTIF($B36:$AF36,2) -> 1 | AM36: =COUNTIF($B36:$AF36,"DO") -> 3 | AN36: =COUNTIF($B36:$AF36,"R") -> 0 | AO36: =COUNTIF($B36:$AF36,4) -> 3 | AP36: =COUNTIF($B36:$AF36,5) -> 2 | AQ36: =SUM(AJ36:AN36) -> 24 | AR36: =AP36+AO36+AN36+AL36+AK36+AJ36+((AH36+AI36)/2) -> 28.5
A38: MICABALO | B38: DO | C38: DO | D38: 3 | E38: 1 | F38: DO | G38: 2 | H38: 3 | I38: 1 | J38: R | K38: DO | L38: 2 | M38: 3 | N38: 1 | O38: 3 | P38: 1 | Q38: 3 | R38: 4 | S38: 3 | T38: 1 | U38: 3 | V38: 1 | W38: 2 | X38: 3 | Y38: 1 | Z38: 3 | AA38: 1 | AB38: 3 | AC38: 4 | AD38: 5 | AG38: =AR38 -> 26.5 | AH38: =COUNTIF($B38:$AF38,4) -> 2 | AI38: =COUNTIF($B38:$AF38,5) -> 1 | AJ38: =COUNTIF($B38:$AF38,3) -> 10 | AK38: =COUNTIF($B38:$AF38,1) -> 8 | AL38: =COUNTIF($B38:$AF38,2) -> 3 | AM38: =COUNTIF($B38:$AF38,"DO") -> 4 | AN38: =COUNTIF($B38:$AF38,"R") -> 1 | AO38: =COUNTIF($B38:$AF38,4) -> 2 | AP38: =COUNTIF($B38:$AF38,5) -> 1 | AQ38: =SUM(AJ38:AN38) -> 26 | AR38: =AP38+AO38+AN38+AL38+AK38+AJ38+((AH38+AI38)/2) -> 26.5
A40: PACTURANAN | B40: 4 | C40: 3 | D40: 1 | E40: DO | F40: 5 | G40: 1 | H40: 3 | I40: 1 | J40: R | K40: DO | L40: DO | M40: 2 | N40: 2 | O40: 5 | P40: 1 | Q40: 3 | R40: 1 | S40: DO | T40: 5 | U40: 1 | V40: 2 | W40: 3 | X40: 1 | Y40: 2 | Z40: DO | AA40: 2 | AB40: 3 | AC40: 1 | AD40: 3 | AG40: =AR40 -> 26 | AH40: =COUNTIF($B40:$AF40,4) -> 1 | AI40: =COUNTIF($B40:$AF40,5) -> 3 | AJ40: =COUNTIF($B40:$AF40,3) -> 6 | AK40: =COUNTIF($B40:$AF40,1) -> 8 | AL40: =COUNTIF($B40:$AF40,2) -> 5 | AM40: =COUNTIF($B40:$AF40,"DO") -> 5 | AN40: =COUNTIF($B40:$AF40,"R") -> 1 | AO40: =COUNTIF($B40:$AF40,4) -> 1 | AP40: =COUNTIF($B40:$AF40,5) -> 3 | AQ40: =SUM(AJ40:AN40) -> 25 | AR40: =AP40+AO40+AN40+AL40+AK40+AJ40+((AH40+AI40)/2) -> 26
A42: RUDINAS | B42: 3 | C42: 1 | D42: 2 | E42: 3 | F42: 1 | G42: 3 | H42: 1 | I42: 3 | J42: 1 | K42: 3 | L42: 1 | M42: DO | N42: 3 | O42: 1 | P42: 2 | Q42: 2 | R42: 5 | S42: 1 | T42: R | U42: DO | V42: 3 | W42: 1 | X42: 3 | Y42: 1 | Z42: 3 | AA42: 1 | AB42: 2 | AC42: 3 | AD42: 4 | AG42: =AR42 -> 28 | AH42: =COUNTIF($B42:$AF42,4) -> 1 | AI42: =COUNTIF($B42:$AF42,5) -> 1 | AJ42: =COUNTIF($B42:$AF42,3) -> 10 | AK42: =COUNTIF($B42:$AF42,1) -> 10 | AL42: =COUNTIF($B42:$AF42,2) -> 4 | AM42: =COUNTIF($B42:$AF42,"DO") -> 2 | AN42: =COUNTIF($B42:$AF42,"R") -> 1 | AO42: =COUNTIF($B42:$AF42,4) -> 1 | AP42: =COUNTIF($B42:$AF42,5) -> 1 | AQ42: =SUM(AJ42:AN42) -> 27 | AR42: =AP42+AO42+AN42+AL42+AK42+AJ42+((AH42+AI42)/2) -> 28
A44: LUSPO | B44: 5 | C44: 1 | D44: DO | E44: DO | F44: 3 | G44: 1 | H44: 2 | I44: 2 | J44: 5 | K44: 1 | L44: 3 | M44: 1 | N44: 3 | O44: 4 | P44: 3 | Q44: 1 | R44: DO | S44: DO | T44: 3 | U44: 4 | V44: 3 | W44: 1 | X44: 2 | Y44: 3 | Z44: 1 | AA44: 3 | AB44: 1 | AC44: R | AD44: R | AG44: =AR44 -> 27 | AH44: =COUNTIF($B44:$AF44,4) -> 2 | AI44: =COUNTIF($B44:$AF44,5) -> 2 | AJ44: =COUNTIF($B44:$AF44,3) -> 8 | AK44: =COUNTIF($B44:$AF44,1) -> 8 | AL44: =COUNTIF($B44:$AF44,2) -> 3 | AM44: =COUNTIF($B44:$AF44,"DO") -> 4 | AN44: =COUNTIF($B44:$AF44,"R") -> 2 | AO44: =COUNTIF($B44:$AF44,4) -> 2 | AP44: =COUNTIF($B44:$AF44,5) -> 2 | AQ44: =SUM(AJ44:AN44) -> 25 | AR44: =AP44+AO44+AN44+AL44+AK44+AJ44+((AH44+AI44)/2) -> 27
X46: .
A47: Legend: | D47: 1 | E47: - | F47: 0000H | H47: - | I47: 0800H | M47: R | N47: - | O47: 0800H | Q47: - | R47: 1700H
D48: 2 | E48: - | F48: 0800H | H48: - | I48: 1600H | M48: DO | N48: - | O48: Day off
D49: 3 | E49: - | F49: 1600H | H49: - | I49: 2400H
D50: 4 | E50: - | F50: 0000H | H50: - | I50: 1200H
D51: 5 | E51: - | F51: 1200H | H51: - | I51: 0000H
A53: Prepared By: | L53: Reviewed By: | Y53: Noted By:
B55: N.D.M. ALFECHE | N55: E.L. ADIONG | AA55: J.M.M. MATA
B56: Engineer II | N56: Prin. Engr. A, GPD | AA56: Division Manager, GPD
A58: ENGINEER II SHIFTING SCHEDULE
A59: For the month of February 2024
A60: Name of | B60: THU | C60: FRI | D60: SAT | E60: SUN | F60: MON | G60: TUE | H60: WED | I60: THU | J60: FRI | K60: SAT | L60: SUN | M60: MON | N60: TUE | O60: WED | P60: THU | Q60: FRI | R60: SAT | S60: SUN | T60: MON | U60: TUE | V60: WED | W60: THU | X60: FRI | Y60: SAT | Z60: SUN | AA60: MON | AB60: TUE | AC60: WED | AD60: THU
...

Sheet Sheet3
A1: SUMMARY OF DUTIES FOR 2 PE-A AND 6 ENGR II
A3: SHIFTERS | B3: 3RD SHIFT | C3: 1ST SHIFT | D3: 2ND SHIFT | E3: REGULAR DUTY | F3: TOTAL DAYS
A4: 1. MACUNTE | B4: =VLOOKUP(Sheet1!$AH91,Sheet1!$AH$91:$AO$105,4) -> 7 | C4: =VLOOKUP(Sheet1!$AH91,Sheet1!$AH$91:$AO$105,5) -> 8 | D4: =VLOOKUP(Sheet1!$AH91,Sheet1!$AH$91:$AO$105,6) -> 6 | E4: =VLOOKUP(Sheet1!$AH91,Sheet1!$AH$91:$AO$105,8) -> 5 | F4: =SUM(B4:E4) -> 26
A5: 2. PE-A 1 | B5: =VLOOKUP(Sheet1!$AH93,Sheet1!$AH$91:$AO$105,4) -> 7 | C5: =VLOOKUP(Sheet1!$AH93,Sheet1!$AH$91:$AO$105,5) -> 8 | D5: =VLOOKUP(Sheet1!$AH93,Sheet1!$AH$91:$AO$105,6) -> 6 | E5: =VLOOKUP(Sheet1!$AH93,Sheet1!$AH$91:$AO$105,8) -> 5 | F5: =SUM(B5:E5) -> 26
A6: 3. PE-A 2 | B6: =VLOOKUP(Sheet1!$AH95,Sheet1!$AH$91:$AO$105,4) -> 7 | C6: =VLOOKUP(Sheet1!$AH95,Sheet1!$AH$91:$AO$105,5) -> 8 | D6: =VLOOKUP(Sheet1!$AH95,Sheet1!$AH$91:$AO$105,6) -> 6 | E6: =VLOOKUP(Sheet1!$AH95,Sheet1!$AH$91:$AO$105,8) -> 5 | F6: =SUM(B6:E6) -> 26
A7: 4. ALFECHE | B7: =VLOOKUP(Sheet1!$AH97,Sheet1!$AH$91:$AO$105,4) -> 7 | C7: =VLOOKUP(Sheet1!$AH97,Sheet1!$AH$91:$AO$105,5) -> 8 | D7: =VLOOKUP(Sheet1!$AH97,Sheet1!$AH$91:$AO$105,6) -> 6 | E7: =VLOOKUP(Sheet1!$AH97,Sheet1!$AH$91:$AO$105,8) -> 5 | F7: =SUM(B7:E7) -> 26
A8: 5. MICABALO | B8: =VLOOKUP(Sheet1!$AH99,Sheet1!$AH$91:$AO$105,4) -> 7 | C8: =VLOOKUP(Sheet1!$AH99,Sheet1!$AH$91:$AO$105,5) -> 8 | D8: =VLOOKUP(Sheet1!$AH99,Sheet1!$AH$91:$AO$105,6) -> 6 | E8: =VLOOKUP(Sheet1!$AH99,Sheet1!$AH$91:$AO$105,8) -> 5 | F8: =SUM(B8:E8) -> 26
A9: 6. PACTURANAN | B9: =VLOOKUP(Sheet1!$AH101,Sheet1!$AH$91:$AO$105,4) -> 7 | C9: =VLOOKUP(Sheet1!$AH101,Sheet1!$AH$91:$AO$105,5) -> 8 | D9: =VLOOKUP(Sheet1!$AH101,Sheet1!$AH$91:$AO$105,6) -> 6 | E9: =VLOOKUP(Sheet1!$AH101,Sheet1!$AH$91:$AO$105,8) -> 5 | F9: =SUM(B9:E9) -> 26
A10: 7. RUDINAS | B10: =VLOOKUP(Sheet1!$AH103,Sheet1!$AH$91:$AO$105,4) -> 9 | C10: =VLOOKUP(Sheet1!$AH103,Sheet1!$AH$91:$AO$105,5) -> 8 | D10: =VLOOKUP(Sheet1!$AH103,Sheet1!$AH$91:$AO$105,6) -> 4 | E10: =VLOOKUP(Sheet1!$AH103,Sheet1!$AH$91:$AO$105,8) -> 4 | F10: =SUM(B10:E10) -> 25
A11: 8. LUSPO | B11: =VLOOKUP(Sheet1!$AH105,Sheet1!$AH$91:$AO$105,4) -> 7 | C11: =VLOOKUP(Sheet1!$AH105,Sheet1!$AH$91:$AO$105,5) -> 8 | D11: =VLOOKUP(Sheet1!$AH105,Sheet1!$AH$91:$AO$105,6) -> 6 | E11: =VLOOKUP(Sheet1!$AH105,Sheet1!$AH$91:$AO$105,8) -> 5 | F11: =SUM(B11:E11) -> 26
A21: Prepared By: | C21: Reviewed By: | E21: Noted By:
B23: J.J. RUDINAS | D23: E.L. ADIONG | F23: J.M.M. MATA
B24: Engineer II | D24: Prin. Engr. A, GPD | F24: Division Manager, GPD
A32: SUMMARY OF DUTIES FOR 3 PE-A AND 6 ENGR II
A34: SHIFTERS | B34: 3RD SHIFT | C34: 1ST SHIFT | D34: 2ND SHIFT | E34: REGULAR DUTY | F34: TOTAL DAYS
A35: 1. MACUNTE | B35: =VLOOKUP(Sheet1!$AH$122,Sheet1!$AH$122:$AS$139,4) -> 10 | C35: =VLOOKUP(Sheet1!$AH$122,Sheet1!$AH$122:$AS$139,5) -> 9 | D35: =VLOOKUP(Sheet1!$AH$122,Sheet1!$AH$122:$AS$139,6) -> 5 | E35: =VLOOKUP(Sheet1!$AH$122,Sheet1!$AH$122:$AS$139,8) -> 3 | F35: =SUM(B35:E35) -> 27
A36: 2. PE-A 1 | B36: =VLOOKUP(Sheet1!$AH$124,Sheet1!$AH$122:$AS$139,4) -> 10 | C36: =VLOOKUP(Sheet1!$AH$124,Sheet1!$AH$122:$AS$139,5) -> 9 | D36: =VLOOKUP(Sheet1!$AH$124,Sheet1!$AH$122:$AS$139,6) -> 5 | E36: =VLOOKUP(Sheet1!$AH$124,Sheet1!$AH$122:$AS$139,8) -> 3 | F36: =SUM(B36:E36) -> 27
A37: 3. PE-A 2 | B37: =VLOOKUP(Sheet1!$AH$126,Sheet1!$AH$122:$AS$139,4) -> 10 | C37: =VLOOKUP(Sheet1!$AH$126,Sheet1!$AH$122:$AS$139,5) -> 9 | D37: =VLOOKUP(Sheet1!$AH$126,Sheet1!$AH$122:$AS$139,6) -> 5 | E37: =VLOOKUP(Sheet1!$AH$126,Sheet1!$AH$122:$AS$139,8) -> 3 | F37: =SUM(B37:E37) -> 27
A38: 4. PE-A 3 | B38: =VLOOKUP(Sheet1!$AH$128,Sheet1!$AH$122:$AS$139,4) -> 7 | C38: =VLOOKUP(Sheet1!$AH$128,Sheet1!$AH$122:$AS$139,5) -> 8 | D38: =VLOOKUP(Sheet1!$AH$128,Sheet1!$AH$122:$AS$139,6) -> 4 | E38: =VLOOKUP(Sheet1!$AH$128,Sheet1!$AH$122:$AS$139,8) -> 5 | F38: =SUM(B38:E38) -> 24
A39: 5. ALFECHE | B39: =VLOOKUP(Sheet1!$AH$130,Sheet1!$AH$122:$AS$139,4) -> 10 | C39: =VLOOKUP(Sheet1!$AH$130,Sheet1!$AH$122:$AS$139,5) -> 9 | D39: =VLOOKUP(Sheet1!$AH$130,Sheet1!$AH$122:$AS$139,6) -> 5 | E39: =VLOOKUP(Sheet1!$AH$130,Sheet1!$AH$122:$AS$139,8) -> 3 | F39: =SUM(B39:E39) -> 27
A40: 6. MICABALO | B40: =VLOOKUP(Sheet1!$AH$132,Sheet1!$AH$122:$AS$139,4) -> 10 | C40: =VLOOKUP(Sheet1!$AH$132,Sheet1!$AH$122:$AS$139,5) -> 9 | D40: =VLOOKUP(Sheet1!$AH$132,Sheet1!$AH$122:$AS$139,6) -> 5 | E40: =VLOOKUP(Sheet1!$AH$132,Sheet1!$AH$122:$AS$139,8) -> 3 | F40: =SUM(B40:E40) -> 27
A41: 7. PACTURANAN | B41: =VLOOKUP(Sheet1!$AH$134,Sheet1!$AH$122:$AS$139,4) -> 10 | C41: =VLOOKUP(Sheet1!$AH$134,Sheet1!$AH$122:$AS$139,5) -> 9 | D41: =VLOOKUP(Sheet1!$AH$134,Sheet1!$AH$122:$AS$139,6) -> 5 | E41: =VLOOKUP(Sheet1!$AH$134,Sheet1!$AH$122:$AS$139,8) -> 3 | F41: =SUM(B41:E41) -> 27
A42: 8. RUDINAS | B42: =VLOOKUP(Sheet1!$AH$136,Sheet1!$AH$122:$AS$139,4) -> 9 | C42: =VLOOKUP(Sheet1!$AH$136,Sheet1!$AH$122:$AS$139,5) -> 8 | D42: =VLOOKUP(Sheet1!$AH$136,Sheet1!$AH$122:$AS$139,6) -> 4 | E42: =VLOOKUP(Sheet1!$AH$136,Sheet1!$AH$122:$AS$139,8) -> 4 | F42: =SUM(B42:E42) -> 25
A43: 9. LUSPO | B43: =VLOOKUP(Sheet1!$AH$138,Sheet1!$AH$122:$AS$139,4) -> 10 | C43: =VLOOKUP(Sheet1!$AH$138,Sheet1!$AH$122:$AS$139,5) -> 9 | D43: =VLOOKUP(Sheet1!$AH$138,Sheet1!$AH$122:$AS$139,6) -> 5 | E43: =VLOOKUP(Sheet1!$AH$138,Sheet1!$AH$122:$AS$139,8) -> 3 | F43: =SUM(B43:E43) -> 27
A53: Prepared By: | C53: Reviewed By: | E53: Noted By:
B55: J.J. RUDINAS | D55: E.L. ADIONG | F55: J.M.M. MATA
B56: Engineer II | D56: Prin. Engr. A, GPD | F56: Division Manager, GPD

Sheet Sheet2
A1: ENGINEER II SHIFTING SCHEDULE
A2: For the month of November 2023
A3: Name of | B3: WED | C3: THU | D3: FRI | E3: SAT | F3: SUN | G3: MON | H3: TUE | I3: WED | J3: THU | K3: FRI | L3: SAT | M3: SUN | N3: MON | O3: TUE | P3: WED | Q3: THU | R3: FRI | S3: SAT | T3: SUN | U3: MON | V3: TUE | W3: WED | X3: THU | Y3: FRI | Z3: SAT | AA3: SUN | AB3: MON | AC3: TUE | AD3: WED | AE3: THU
A4: Personnel | B4: 1 | C4: 2 | D4: 3 | E4: 4 | F4: 5 | G4: 6 | H4: 7 | I4: 8 | J4: 9 | K4: 10 | L4: 11 | M4: 12 | N4: 13 | O4: 14 | P4: 15 | Q4: 16 | R4: 17 | S4: 18 | T4: 19 | U4: 20 | V4: 21 | W4: 22 | X4: 23 | Y4: 24 | Z4: 25 | AA4: 26 | AB4: 27 | AC4: 28 | AD4: 29 | AE4: 30 | AG4: 24 | AJ4: 3 | AK4: 1 | AL4: 2 | AM4: DO | AN4: R | AO4: 4 | AP4: 5
A5: MACUNTE | B5: R | C5: R | D5: R | E5: DO | F5: DO | G5: R | H5: R | I5: R | J5: R | K5: R | L5: 2 | M5: DO | N5: R | O5: R | P5: R | Q5: R | R5: R | S5: DO | T5: 2 | U5: R | V5: R | W5: R | X5: R | Y5: R | Z5: DO | AA5: 2 | AB5: R | AC5: R | AD5: R | AE5: R | AG5: =AR5 -> 25 | AJ5: =COUNTIF($B5:$AF5,3) -> 0 | AK5: =COUNTIF($B5:$AF5,1) -> 0 | AL5: =COUNTIF($B5:$AF5,2) -> 3 | AM5: =COUNTIF($B5:$AF5,"DO") -> 5 | AN5: =COUNTIF($B5:$AF5,"R") -> 22 | AO5: =COUNTIF($B5:$AF5,4) -> 0 | AP5: =COUNTIF($B5:$AF5,5) -> 0 | AQ5: =SUM(AJ5:AN5) -> 30 | AR5: =AP5+AO5+AN5+AL5+AK5+AJ5 -> 25 | AT5: =COUNTIF($B5:$P5,3) -> 0 | AU5: =COUNTIF($B5:$P5,1) -> 0 | AV5: =COUNTIF($B5:$P5,2) -> 1 | AW5: =COUNTIF($B5:$P5,"DO") -> 3 | AX5: =COUNTIF($B5:$P5,"R") -> 11 | AY5: =SUM(AT5:AX5) -> 15
A7: ALFECHE | B7: 4 | C7: 5 | D7: 1 | E7: DO | F7: 5 | G7: 1 | H7: 2 | I7: DO | J7: DO | K7: R | L7: 3 | M7: 4 | N7: 5 | O7: 1 | P7: 3 | Q7: 4 | R7: 5 | S7: 1 | T7: 3 | U7: 4 | V7: 3 | W7: 1 | X7: 5 | Y7: 1 | Z7: 5 | AA7: 1 | AB7: 3 | AC7: 1 | AD7: DO | AE7: 5 | AG7: =AR7 -> 26 | AJ7: =COUNTIF($B7:$AF7,3) -> 5 | AK7: =COUNTIF($B7:$AF7,1) -> 8 | AL7: =COUNTIF($B7:$AF7,2) -> 1 | AM7: =COUNTIF($B7:$AF7,"DO") -> 4 | AN7: =COUNTIF($B7:$AF7,"R") -> 1 | AO7: =COUNTIF($B7:$AF7,4) -> 4 | AP7: =COUNTIF($B7:$AF7,5) -> 7 | AQ7: =SUM(AJ7:AN7) -> 19 | AR7: =AP7+AO7+AN7+AL7+AK7+AJ7 -> 26 | AT7: =COUNTIF($B7:$P7,3) -> 2 | AU7: =COUNTIF($B7:$P7,1) -> 3 | AV7: =COUNTIF($B7:$P7,2) -> 1 | AW7: =COUNTIF($B7:$P7,"DO") -> 3 | AX7: =COUNTIF($B7:$P7,"R") -> 1 | AY7: =SUM(AT7:AX7) -> 10
Z8: R | AA8: R
A9: MICABALO | B9: R | C9: R | D9: DO | E9: 5 | F9: 1 | G9: 2 | H9: 3 | I9: 4 | J9: 2 | K9: 3 | L9: 1 | M9: 5 | N9: 1 | O9: 3 | P9: 4 | Q9: 5 | R9: 1 | S9: 2 | T9: DO | U9: 5 | V9: 1 | W9: 5 | X9: 1 | Y9: 2 | Z9: 2 | AA9: 5 | AB9: 1 | AC9: 3 | AD9: 4 | AE9: 3 | AG9: =AR9 -> 28 | AJ9: =COUNTIF($B9:$AF9,3) -> 5 | AK9: =COUNTIF($B9:$AF9,1) -> 7 | AL9: =COUNTIF($B9:$AF9,2) -> 5 | AM9: =COUNTIF($B9:$AF9,"DO") -> 2 | AN9: =COUNTIF($B9:$AF9,"R") -> 2 | AO9: =COUNTIF($B9:$AF9,4) -> 3 | AP9: =COUNTIF($B9:$AF9,5) -> 6 | AQ9: =SUM(AJ9:AN9) -> 21 | AR9: =AP9+AO9+AN9+AL9+AK9+AJ9 -> 28 | AT9: =COUNTIF($B9:$P9,3) -> 3 | AU9: =COUNTIF($B9:$P9,1) -> 3 | AV9: =COUNTIF($B9:$P9,2) -> 2 | AW9: =COUNTIF($B9:$P9,"DO") -> 1 | AX9: =COUNTIF($B9:$P9,"R") -> 2 | AY9: =SUM(AT9:AX9) -> 11
A11: PACTURANAN | B11: 3 | C11: 4 | D11: 3 | E11: 4 | F11: DO | G11: 5 | H11: 1 | I11: 5 | J11: 1 | K11: 5 | L11: 1 | M11: DO | N11: 3 | O11: 4 | P11: 5 | Q11: 1 | R11: 3 | S11: 4 | T11: DO | U11: 3 | V11: 4 | W11: 3 | X11: 1 | Y11: 5 | Z11: 1 | AA11: DO | AB11: 3 | AC11: 4 | AD11: 3 | AE11: 4 | AG11: =AR11 -> 26 | AJ11: =COUNTIF($B11:$AF11,3) -> 8 | AK11: =COUNTIF($B11:$AF11,1) -> 6 | AL11: =COUNTIF($B11:$AF11,2) -> 0 | AM11: =COUNTIF($B11:$AF11,"DO") -> 4 | AN11: =COUNTIF($B11:$AF11,"R") -> 0 | AO11: =COUNTIF($B11:$AF11,4) -> 7 | AP11: =COUNTIF($B11:$AF11,5) -> 5 | AQ11: =SUM(AJ11:AN11) -> 18 | AR11: =AP11+AO11+AN11+AL11+AK11+AJ11 -> 26 | AT11: =COUNTIF($B11:$P11,3) -> 3 | AU11: =COUNTIF($B11:$P11,1) -> 3 | AV11: =COUNTIF($B11:$P11,2) -> 0 | AW11: =COUNTIF($B11:$P11,"DO") -> 2 | AX11: =COUNTIF($B11:$P11,"R") -> 0 | AY11: =SUM(AT11:AX11) -> 8
A13: RUDINAS | B13: 5 | C13: 1 | D13: 3 | E13: 1 | F13: 3 | G13: 4 | H13: DO | I13: DO | J13: DO | K13: R | L13: DO | M13: 3 | N13: 4 | O13: 5 | P13: 1 | Q13: 3 | R13: 4 | S13: 5 | T13: 1 | U13: 2 | V13: 3 | W13: 4 | X13: 2 | Y13: 3 | Z13: 1 | AA13: 3 | AB13: 4 | AC13: 5 | AD13: 1 | AE13: 2 | AG13: =AR13 -> 26 | AJ13: =COUNTIF($B13:$AF13,3) -> 7 | AK13: =COUNTIF($B13:$AF13,1) -> 6 | AL13: =COUNTIF($B13:$AF13,2) -> 3 | AM13: =COUNTIF($B13:$AF13,"DO") -> 4 | AN13: =COUNTIF($B13:$AF13,"R") -> 1 | AO13: =COUNTIF($B13:$AF13,4) -> 5 | AP13: =COUNTIF($B13:$AF13,5) -> 4 | AQ13: =SUM(AJ13:AN13) -> 21 | AR13: =AP13+AO13+AN13+AL13+AK13+AJ13 -> 26 | AT13: =COUNTIF($B13:$P13,3) -> 3 | AU13: =COUNTIF($B13:$P13,1) -> 3 | AV13: =COUNTIF($B13:$P13,2) -> 0 | AW13: =COUNTIF($B13:$P13,"DO") -> 4 | AX13: =COUNTIF($B13:$P13,"R") -> 1 | AY13: =SUM(AT13:AX13) -> 11
A15: LUSPO | B15: R | C15: R | D15: 2 | E15: 3 | F15: 4 | G15: 3 | H15: 1 | I15: R | J15: 3 | K15: 4 | L15: 3 | M15: 1 | N15: R | O15: R | P15: R | Q15: DO | R15: 2 | S15: DO | T15: 5 | U15: 1 | V15: 2 | W15: 2 | X15: 3 | Y15: 4 | Z15: 3 | AA15: 4 | AB15: 2 | AC15: 2 | AD15: 5 | AE15: 1 | AG15: =AR15 -> 28 | AJ15: =COUNTIF($B15:$AF15,3) -> 6 | AK15: =COUNTIF($B15:$AF15,1) -> 4 | AL15: =COUNTIF($B15:$AF15,2) -> 6 | AM15: =COUNTIF($B15:$AF15,"DO") -> 2 | AN15: =COUNTIF($B15:$AF15,"R") -> 6 | AO15: =COUNTIF($B15:$AF15,4) -> 4 | AP15: =COUNTIF($B15:$AF15,5) -> 2 | AQ15: =SUM(AJ15:AN15) -> 24 | AR15: =AP15+AO15+AN15+AL15+AK15+AJ15 -> 28 | AT15: =COUNTIF($B15:$P15,3) -> 4 | AU15: =COUNTIF($B15:$P15,1) -> 2 | AV15: =COUNTIF($B15:$P15,2) -> 1 | AW15: =COUNTIF($B15:$P15,"DO") -> 0 | AX15: =COUNTIF($B15:$P15,"R") -> 6 | AY15: =SUM(AT15:AX15) -> 13
A18: Legend: | D18: 1 | E18: - | F18: 0000H | H18: - | I18: 0800H | M18: R | N18: - | O18: 0800H | Q18: - | R18: 1700H
D19: 2 | E19: - | F19: 0800H | H19: - | I19: 1600H | M19: DO | N19: - | O19: Day off
D20: 3 | E20: - | F20: 1600H | H20: - | I20: 2400H
A22: Prepared By: | L22: Reviewed By: | Y22: Noted By:
B24: J.O.H. LUSPO | N24: E.L. ADIONG | AA24: J.M.M. MATA
B25: Engineer II | N25: Prin. Engr. A, GPD | AA25: OIC-Division Manager, GPD

Sheet Sheet4
A1: For the month of May 2024
A2: Name of | B2: WED | C2: THU | D2: FRI | E2: SAT | F2: SUN | G2: MON | H2: TUE | I2: WED | J2: THU | K2: FRI | L2: SAT | M2: SUN | N2: MON | O2: TUE | P2: WED | Q2: THU | R2: FRI | S2: SAT | T2: SUN | U2: MON | V2: TUE | W2: WED | X2: THU | Y2: FRI | Z2: SAT | AA2: SUN | AB2: MON | AC2: TUE | AD2: WED | AE2: THU | AF2: FRI
A3: Personnel | B3: 1 | C3: 2 | D3: 3 | E3: 4 | F3: 5 | G3: 6 | H3: 7 | I3: 8 | J3: 9 | K3: 10 | L3: 11 | M3: 12 | N3: 13 | O3: 14 | P3: 15 | Q3: 16 | R3: 17 | S3: 18 | T3: 19 | U3: 20 | V3: 21 | W3: 22 | X3: 23 | Y3: 24 | Z3: 25 | AA3: 26 | AB3: 27 | AC3: 28 | AD3: 29 | AE3: 30 | AF3: 31 | AG3: 24
A4: MACUNTE | AG4: =AS4 -> 0
A6: ALFECHE | H6: 3 | I6: 1 | J6: DO | K6: DO | L6: 3 | M6: 1 | P6: 3 | Q6: 1 | R6: DO | S6: DO | T6: 3 | U6: 1 | AG6: =AS6 -> 0
H7: R | I7: R | J7: R
A8: MICABALO | X8: 3 | Y8: 1 | Z8: DO | AA8: DO | AB8: DO | AC8: 3 | AD8: 1 | AG8: =AS8 -> 0
A10: PACTURANAN | AG10: =AS10 -> 0
A12: RUDINAS | H12: R | I12: R | J12: R | X12: 3 | Y12: 1 | Z12: DO | AA12: DO | AB12: DO | AC12: DO | AD12: DO | AE12: 3 | AF12: 1 | AG12: =AS12 -> 0
A14: LUSPO | E14: 3 | F14: 1 | G14: DO | H14: DO | I14: DO | J14: 3 | K14: 1 | AD14: 3 | AE14: 1 | AF14: DO | AG14: =AS14 -> 0
